Workbook

Sheet Model Assumptions
A1: MODEL DESCRIPTION:
A2: Client: | B2: IWC
A3: Property: | B3: Boot Hill
A4: Run Date: | B4: 46048.485
A5: Description: | B5: IWC - Boothill - HSM
A6: Scenario Name: | B6: IWC_2025_BTHILL_HSM
A7: Length of Horizon: | B7: =CONCATENATE(B18, " years") -> 50 years
A8: Objective Function: | B8: Max: Net Present Value from Operating Cash Flow
A9: Gross Acres: | B9: 12404.89
A10: G&Y Models: | B10: Stand-table Projection, FastLob & PMRC
A11: Woodstock RSPS File: | B11: Z:\Harvest_Schedules\IWC\IWC_2025_BTHILL_HSM\REPORTS\IWC_2025_BTHILL_HSM_DRAFT6.rsps
A13: MODEL ASSUMPTIONS:
A15: Model Year 1: | B15: 2026
A16: Discount Rate: | B16: 0.05
A17: Inflation Rate: | B17: 1e-07
A18: Planning Period Length: | B18: 50
A19: Plantation Merch Age: | B19: 12
A21: MODEL CONSTRAINTS: | B21: Includes 2026 budgeted stands
B22: Existing Unthinned stands age >20 schedule for clearcut when elligable at age 24
B23: All future stands are thinned at least once and no later than 16 years of age
B24: Max clearcut acres <= 1,500
B25: Natural Non-Convertible stands havrested <= 2% of Plantation harvests annually
A47: PRODUCT PRICES: | B47: =$B$15 -> 2026 | C47: =B47+1 -> 2027 | D47: =C47+1 -> 2028 | E47: =D47+1 -> 2029 | F47: =E47+1 -> 2030 | G47: =F47+1 -> 2031 | H47: =G47+1 -> 2032 | I47: =H47+1 -> 2033 | J47: =I47+1 -> 2034 | ... P47: =O47+1 -> 2040
A48: Pine Pulpwood | B48: 3 | C48: 3.0849 | D48: 3.1592 | E48: 3.2193 | F48: 3.2689 | G48: 3.3113 | H48: 3.3467 | I48: 3.375 | J48: 3.3962 | K48: 3.4175 | L48: 3.4351 | M48: 3.4458 | N48: 3.4599 | O48: 3.4634 | P48: 3.4741
A49: Pine Chipnsaw | B49: 13 | C49: 13.3464 | D49: 13.6474 | E49: 13.9144 | F49: 14.1415 | G49: 14.3346 | H49: 14.4993 | I49: 14.6413 | J49: 14.7549 | K49: 14.8515 | L49: 14.9367 | M49: 15.0105 | N49: 15.0616 | O49: 15.1127 | P49: 15.1525
A50: Pine Sawlog | B50: 19 | C50: 20.042 | D50: 20.978 | E50: 21.7829 | F50: 22.488 | G50: 23.0745 | H50: 23.5737 | I50: 23.998 | J50: 24.3537 | K50: 24.6532 | L50: 24.9028 | M50: 25.1149 | N50: 25.2897 | O50: 25.4456 | P50: 27.2926
A51: Pine Large Sawlog | B51: 29 | C51: 29 | D51: 29 | E51: 29 | F51: 29 | G51: 29 | H51: 29 | I51: 29 | J51: 29 | K51: 29 | L51: 29 | M51: 29 | N51: 29 | O51: 29 | P51: 29
A52: Hardwood Pulp | B52: 8 | C52: 8 | D52: 8 | E52: 8 | F52: 8 | G52: 8 | H52: 8 | I52: 8 | J52: 8 | K52: 8 | L52: 8 | M52: 8 | N52: 8 | O52: 8 | P52: 8
A53: Hardwood Sawlog | B53: 30 | C53: 30 | D53: 30 | E53: 30 | F53: 30 | G53: 30 | H53: 30 | I53: 30 | J53: 30 | K53: 30 | L53: 30 | M53: 30 | N53: 30 | O53: 30 | P53: 30
A55: ZONE 2 PRODUCT PRICES: | B55: =$B$15 -> 2026 | C55: =B55+1 -> 2027 | D55: =C55+1 -> 2028 | E55: =D55+1 -> 2029 | F55: =E55+1 -> 2030 | G55: =F55+1 -> 2031 | H55: =G55+1 -> 2032 | I55: =H55+1 -> 2033 | J55: =I55+1 -> 2034 | ... P55: =O55+1 -> 2040
A56: Pine Pulpwood | B56: 5 | C56: 5.1415 | D56: 5.2653 | E56: 5.3656 | F56: 5.4481 | G56: 5.5189 | H56: 5.5778 | I56: 5.625 | J56: 5.6604 | K56: 5.6958 | L56: 5.7252 | M56: 5.7429 | N56: 5.7665 | O56: 5.7724 | P56: 5.7901
A57: Pine Chipnsaw | B57: 20 | C57: 20.533 | D57: 20.9961 | E57: 21.4067 | F57: 21.7562 | G57: 22.0533 | H57: 22.3067 | I57: 22.5251 | J57: 22.6999 | K57: 22.8484 | L57: 22.9795 | M57: 23.0931 | N57: 23.1717 | O57: 23.2503 | P57: 23.3115
A58: Pine Sawlog | B58: 30 | C58: 31.6453 | D58: 33.1232 | E58: 34.3941 | F58: 35.5074 | G58: 36.4335 | H58: 37.2217 | I58: 37.8916 | J58: 38.4532 | K58: 38.9261 | L58: 39.3202 | M58: 39.6552 | N58: 39.931 | O58: 40.1773 | P58: 43.0936
A59: Pine Large Sawlog | B59: 0 | C59: 0 | D59: 0 | E59: 0 | F59: 0 | G59: 0 | H59: 0 | I59: 0 | J59: 0 | K59: 0 | L59: 0 | M59: 0 | N59: 0 | O59: 0 | P59: 0
A60: Hardwood Pulp | B60: 8 | C60: 8 | D60: 8 | E60: 8 | F60: 8 | G60: 8 | H60: 8 | I60: 8 | J60: 8 | K60: 8 | L60: 8 | M60: 8 | N60: 8 | O60: 8 | P60: 8
A61: Hardwood Sawlog | B61: 30 | C61: 30 | D61: 30 | E61: 30 | F61: 30 | G61: 30 | H61: 30 | I61: 30 | J61: 30 | K61: 30 | L61: 30 | M61: 30 | N61: 30 | O61: 30 | P61: 30
B63: Zone 1 PRODUCT SPECS: | C63: Min DBH | D63: Top DOB | E63: Merch Length | F63: % Degrade to pulp | H63: Zone 2 PRODUCT SPECS: | I63: Min DBH | J63: Top DOB | K63: Merch Length | L63: % Degrade to pulp
B64: Pine Pulpwood | C64: 4.6 | D64: 3 | E64: 20 | H64: Pine Pulpwood | I64: 4.6 | J64: 3 | K64: 20
B65: Pine Chipnsaw | C65: 8.6 | D65: 6 | E65: 24 | F65: 10 | H65: Pine Chipnsaw | I65: 8.6 | J65: 6 | K65: 16 | L65: 10
B66: Pine Sawlog | C66: 13.6 | D66: 10 | E66: 16 | F66: 10 | H66: Pine Sawlog | I66: 13.6 | J66: 8 | K66: 0 | L66: 10
...

Sheet Finance Report
A1: DISCOUNTED CASH FLOW ANALYSIS
A2: Finance Report
A3: =CONCATENATE('Model Assumptions'!B2, " - ",'Model Assumptions'!B3 ) -> IWC - Boot Hill
A4: ='Model Assumptions'!B5 -> IWC - Boothill - HSM
A6: Calendar Year >> | B6: Model Year 0 | C6: 2026 | D6: =C6+1 -> 2027 | E6: =D6+1 -> 2028 | F6: =E6+1 -> 2029 | G6: =F6+1 -> 2030 | H6: =G6+1 -> 2031 | I6: =H6+1 -> 2032 | J6: =I6+1 -> 2033 | K6: =J6+1 -> 2034 | ... AZ6: =AY6+1 -> 2075
A7: Model Discount Period >> | B7: 0 | C7: 1 | D7: =C7+1 -> 2 | E7: =D7+1 -> 3 | F7: =E7+1 -> 4 | G7: =F7+1 -> 5 | H7: =G7+1 -> 6 | I7: =H7+1 -> 7 | J7: =I7+1 -> 8 | K7: =J7+1 -> 9 | ... AZ7: =AY7+1 -> 50
A9: Total Acres | B9: 12404.89 | C9: 12404.89 | D9: 12404.89 | E9: 12404.89 | F9: 12404.89 | G9: 12404.89 | H9: 12404.89 | I9: 12404.89 | J9: 12404.89 | K9: 12404.89 | L9: 12404.89 | M9: 12404.89 | N9: 12404.89 | O9: 12404.89 | P9: 12404.89 | Q9: 12404.89 | R9: 12404.89 | S9: 12404.89 | T9: 12404.89 | U9: 12404.89 | V9: 12404.89 | W9: 12404.89 | X9: 12404.89 | Y9: 12404.89 | Z9: 12404.89 | AA9: 12404.89 | AB9: 12404.89 | AC9: 12404.89 | AD9: 12404.89 | AE9: 12404.89 | AF9: 12404.89 | AG9: 12404.89 | AH9: 12404.89 | AI9: 12404.89 | AJ9: 12404.89 | AK9: 12404.89 | AL9: 12404.89 | AM9: 12404.89 | AN9: 12404.89 | AO9: 12404.89 | AP9: 12404.89 | AQ9: 12404.89 | AR9: 12404.89 | AS9: 12404.89 | AT9: 12404.89 | AU9: 12404.89 | AV9: 12404.89 | AW9: 12404.89 | AX9: 12404.89 | AY9: 12404.89 | AZ9: 12404.89
A10: Productive Plantation Acres | B10: 8762.98 | C10: 8762.98 | D10: 8762.98 | E10: 8762.98 | F10: 8762.98 | G10: 8762.98 | H10: 8762.98 | I10: 8762.98 | J10: 8762.98 | K10: 8762.98 | L10: 8762.98 | M10: 8762.98 | N10: 8762.98 | O10: 8762.98 | P10: 8762.98 | Q10: 8762.98 | R10: 8762.98 | S10: 8762.98 | T10: 8762.98 | U10: 8762.98 | V10: 8762.98 | W10: 8762.98 | X10: 8762.98 | Y10: 8762.98 | Z10: 8762.98 | AA10: 8762.98 | AB10: 8762.98 | AC10: 8762.98 | AD10: 8762.98 | AE10: 8762.98 | AF10: 8762.98 | AG10: 8762.98 | AH10: 8762.98 | AI10: 8762.98 | AJ10: 8762.98 | AK10: 8762.98 | AL10: 8762.98 | AM10: 8762.98 | AN10: 8762.98 | AO10: 8762.98 | AP10: 8762.98 | AQ10: 8762.98 | AR10: 8762.98 | AS10: 8762.98 | AT10: 8762.98 | AU10: 8762.98 | AV10: 8762.98 | AW10: 8762.98 | AX10: 8762.98 | AY10: 8762.98 | AZ10: 8762.98
A11: Natural Convertible Acres | B11: 611.17 | C11: 611.17 | D11: 611.17 | E11: 611.17 | F11: 611.17 | G11: 611.17 | H11: 611.17 | I11: 611.17 | J11: 611.17 | K11: 611.17 | L11: 611.17 | M11: 611.17 | N11: 611.17 | O11: 611.17 | P11: 611.17 | Q11: 611.17 | R11: 611.17 | S11: 611.17 | T11: 611.17 | U11: 611.17 | V11: 611.17 | W11: 611.17 | X11: 611.17 | Y11: 611.17 | Z11: 611.17 | AA11: 611.17 | AB11: 611.17 | AC11: 611.17 | AD11: 611.17 | AE11: 611.17 | AF11: 611.17 | AG11: 611.17 | AH11: 611.17 | AI11: 611.17 | AJ11: 611.17 | AK11: 611.17 | AL11: 611.17 | AM11: 611.17 | AN11: 611.17 | AO11: 611.17 | AP11: 611.17 | AQ11: 611.17 | AR11: 611.17 | AS11: 611.17 | AT11: 611.17 | AU11: 611.17 | AV11: 611.17 | AW11: 611.17 | AX11: 611.17 | AY11: 611.17 | AZ11: 611.17
A12: Non-Converitble Acres | B12: 3030.74 | C12: 3030.74 | D12: 3030.74 | E12: 3030.74 | F12: 3030.74 | G12: 3030.74 | H12: 3030.74 | I12: 3030.74 | J12: 3030.74 | K12: 3030.74 | L12: 3030.74 | M12: 3030.74 | N12: 3030.74 | O12: 3030.74 | P12: 3030.74 | Q12: 3030.74 | R12: 3030.74 | S12: 3030.74 | T12: 3030.74 | U12: 3030.74 | V12: 3030.74 | W12: 3030.74 | X12: 3030.74 | Y12: 3030.74 | Z12: 3030.74 | AA12: 3030.74 | AB12: 3030.74 | AC12: 3030.74 | AD12: 3030.74 | AE12: 3030.74 | AF12: 3030.74 | AG12: 3030.74 | AH12: 3030.74 | AI12: 3030.74 | AJ12: 3030.74 | AK12: 3030.74 | AL12: 3030.74 | AM12: 3030.74 | AN12: 3030.74 | AO12: 3030.74 | AP12: 3030.74 | AQ12: 3030.74 | AR12: 3030.74 | AS12: 3030.74 | AT12: 3030.74 | AU12: 3030.74 | AV12: 3030.74 | AW12: 3030.74 | AX12: 3030.74 | AY12: 3030.74 | AZ12: 3030.74
A14: Total Available Acres | B14: 11874.6 | C14: 11874.6 | D14: 11874.6 | E14: 11874.6 | F14: 11874.6 | G14: 11874.6 | H14: 11874.6 | I14: 11874.6 | J14: 11874.6 | K14: 11874.6 | L14: 11874.6 | M14: 11874.6 | N14: 11874.6 | O14: 11874.6 | P14: 11874.6 | Q14: 11874.6 | R14: 11874.6 | S14: 11874.6 | T14: 11874.6 | U14: 11874.6 | V14: 11874.6 | W14: 11874.6 | X14: 11874.6 | Y14: 11874.6 | Z14: 11874.6 | AA14: 11874.6 | AB14: 11874.6 | AC14: 11874.6 | AD14: 11874.6 | AE14: 11874.6 | AF14: 11874.6 | AG14: 11874.6 | AH14: 11874.6 | AI14: 11874.6 | AJ14: 11874.6 | AK14: 11874.6 | AL14: 11874.6 | AM14: 11874.6 | AN14: 11874.6 | AO14: 11874.6 | AP14: 11874.6 | AQ14: 11874.6 | AR14: 11874.6 | AS14: 11874.6 | AT14: 11874.6 | AU14: 11874.6 | AV14: 11874.6 | AW14: 11874.6 | AX14: 11874.6 | AY14: 11874.6 | AZ14: 11874.6
A15: Growth - Total Volume | B15: 616852.08 | C15: 67430.277 | D15: 62119.332 | E15: 56728.523 | F15: 54309.616 | G15: 53194.82 | H15: 51978.589 | I15: 46836.864 | J15: 41172.279 | K15: 43513.89 | L15: 36082.925 | M15: 54512.169 | N15: 75970.046 | O15: 100219.13 | P15: 50849.684 | Q15: 33243.495 | R15: 68481.107 | S15: 35498.138 | T15: 40248.505 | U15: 34024.735 | V15: 75639.462 | W15: 95963.804 | X15: 39001.232 | Y15: 55823.519 | Z15: 49482.356 | AA15: 87161.472 | AB15: 34513.631 | AC15: 57182.297 | AD15: 86135.457 | AE15: 37810.579 | AF15: 35215.558 | AG15: 43537.085 | AH15: 46223.153 | AI15: 43090.038 | AJ15: 33262.063 | AK15: 47488.787 | AL15: 72909.334 | AM15: 107708.85 | AN15: 46058.733 | AO15: 38907.705 | AP15: 37193.475 | AQ15: 34996.877 | AR15: 48017.018 | AS15: 27730.356 | AT15: 32034.473 | AU15: 34937.333 | AV15: 22212.194 | AW15: 61482.769 | AX15: 26118.376 | AY15: 22244.457 | AZ15: 9133.5185
A16: Average Growth (vol/ac) | B16: =IF(B15=0,0,B15/B14) -> 51.947188 | C16: =IF(C15=0,0,C15/C14) -> 5.6785304 | D16: =IF(D15=0,0,D15/D14) -> 5.2312779 | E16: =IF(E15=0,0,E15/E14) -> 4.7772997 | F16: =IF(F15=0,0,F15/F14) -> 4.5735954 | G16: =IF(G15=0,0,G15/G14) -> 4.4797147 | H16: =IF(H15=0,0,H15/H14) -> 4.3772918 | I16: =IF(I15=0,0,I15/I14) -> 3.9442899 | ... AZ16: =IF(AZ15=0,0,AZ15/AZ14) -> 0.76916431
A19: Harvest Acres | B19: 0 | C19: 919.96 | D19: 193.34 | E19: 699.1804 | F19: 576.8 | G19: 421.71 | H19: 119.68 | I19: 645.2214 | J19: 1479.316 | K19: 817.0594 | L19: 703.2174 | M19: 459.6524 | N19: 1242.6004 | O19: 662.5206 | P19: 1338.2898 | Q19: 929.28 | R19: 809.49 | S19: 453.22 | T19: 213.74 | U19: 981.9564 | V19: 273.6928 | W19: 365.9684 | X19: 254.00407 | Y19: 1626.1983 | Z19: 2098.8264 | AA19: 251.34 | AB19: 664.15 | AC19: 345.62 | AD19: 1058.01 | AE19: 251.9736 | AF19: 1081.33 | AG19: 1402.99 | AH19: 347.19 | AI19: 215.14 | AJ19: 984.0868 | AK19: 858.55 | AL19: 412.0532 | AM19: 337.29 | AN19: 1312.085 | AO19: 1667.4954 | AP19: 1326.6564 | AQ19: 681.69 | AR19: 558.9724 | AS19: 1125.025 | AT19: 207.81 | AU19: 1193.5536 | AV19: 577.3024 | AW19: 186.6002 | AX19: 330.6838 | AY19: 1501.39 | AZ19: 2222.5636
A20: Total Harvest Volume (tons) | B20: 0 | C20: 47414.973 | D20: 4751.7809 | E20: 61308.341 | F20: 19745.034 | G20: 23397.271 | H20: 2857.348 | I20: 66441.282 | J20: 89801.794 | K20: 56532.3 | L20: 57588.441 | M20: 45747.972 | N20: 132949.63 | O20: 26330.913 | P20: 96057.543 | Q20: 81707.906 | R20: 45318.094 | S20: 16359.018 | T20: 17890.641 | U20: 53193.448 | V20: 23838.226 | W20: 13810.017 | X20: 38950.185 | Y20: 133120.2 | Z20: 238627.42 | AA20: 14458.257 | AB20: 21431.415 | AC20: 13415.615 | AD20: 42202.378 | AE20: 26087.256 | AF20: 40687.067 | AG20: 79747.543 | AH20: 27593.294 | AI20: 12223.322 | AJ20: 74817.252 | AK20: 32247.983 | AL20: 21118.63 | AM20: 9643.3586 | AN20: 102286.55 | AO20: 106829.67 | AP20: 44890.272 | AQ20: 45470.353 | AR20: 46208.697 | AS20: 111441.86 | AT20: 9743.998 | AU20: 81938.098 | AV20: 69260.061 | AW20: 5312.4927 | AX20: 7471.1763 | AY20: 133175 | AZ20: 166268.65
A21: Clearcut Volume (tons) | B21: 0 | C21: 37455.666 | D21: 0 | E21: 54471.547 | F21: 0 | G21: 17966.618 | H21: 0 | I21: 64209.521 | J21: 56261.418 | K21: 3859.4274 | L21: 44501.014 | M21: 43464.637 | N21: 122529.02 | O21: 3686.5475 | P21: 54169.616 | Q21: 63160.981 | R21: 2687.1203 | S21: 1091.2788 | T21: 16164.753 | U21: 21294.946 | V21: 19479.514 | W21: 6447.4673 | X21: 38950.185 | Y21: 105263.92 | Z21: 201762.89 | AA21: 0 | AB21: 0 | AC21: 0 | AD21: 7027.4114 | AE21: 24139.354 | AF21: 0 | AG21: 15710.97 | AH21: 27147.075 | AI21: 0 | AJ21: 55693.603 | AK21: 0 | AL21: 14785.753 | AM21: 0 | AN21: 66449.298 | AO21: 82539.097 | AP21: 2679.9429 | AQ21: 43101.993 | AR21: 38441.187 | AS21: 107267.6 | AT21: 4000.4675 | AU21: 56309.915 | AV21: 69260.061 | AW21: 2104.4252 | AX21: 1122.9453 | AY21: 133165.4 | AZ21: 136551.59
A22: Pine Large Saw Timber | B22: 0 | C22: 1498.1175 | D22: 0 | E22: 2955.033 | F22: 0 | G22: 332.31952 | H22: 0 | I22: 2170.11 | J22: 391.68203 | K22: 0 | L22: 0 | M22: 153.24998 | N22: 8943.018 | O22: 17.180887 | P22: 273.91626 | Q22: 214.47303 | R22: 0 | S22: 0 | T22: 40.363068 | U22: 2810.4066 | V22: 625.60038 | W22: 0 | X22: 0 | Y22: 0 | Z22: 33431.298 | AA22: 0 | AB22: 0 | AC22: 0 | AD22: 1735.1599 | AE22: 5042.629 | AF22: 0 | AG22: 1256.1003 | AH22: 2402.3533 | AI22: 0 | AJ22: 16547.826 | AK22: 0 | AL22: 961.25851 | AM22: 0 | AN22: 12587.13 | AO22: 6100.3956 | AP22: 0 | AQ22: 0 | AR22: 0 | AS22: 9459.3367 | AT22: 0 | AU22: 1141.8714 | AV22: 139.81642 | AW22: 10.319764 | AX22: 4.1222422 | AY22: 4668.9147 | AZ22: 4315.5272
A23: Pine Saw Timber | B23: 0 | C23: 663.581 | D23: 0 | E23: 1163.5334 | F23: 0 | G23: 192.19891 | H23: 0 | I23: 1989.4187 | J23: 1730.5547 | K23: 127.45038 | L23: 2176.8839 | M23: 6408.3695 | N23: 8890.6326 | O23: 426.09889 | P23: 7186.1485 | Q23: 18212.207 | R23: 899.35563 | S23: 126.48941 | T23: 1919.8263 | U23: 1293.6365 | V23: 1766.8829 | W23: 2562.2422 | X23: 17001.716 | Y23: 17988.442 | Z23: 29972.563 | AA23: 0 | AB23: 0 | AC23: 0 | AD23: 0 | AE23: 3168.2347 | AF23: 0 | AG23: 463.4481 | AH23: 1642.4434 | AI23: 0 | AJ23: 428.12452 | AK23: 0 | AL23: 31.152279 | AM23: 0 | AN23: 8520.5548 | AO23: 30561.883 | AP23: 25.055394 | AQ23: 13771.544 | AR23: 12713.628 | AS23: 12149.188 | AT23: 1263.041 | AU23: 5440.4405 | AV23: 33216.445 | AW23: 64.43744 | AX23: 104.99762 | AY23: 10153.318 | AZ23: 6072.6358
A24: Pine Chip-N-Saw | B24: 0 | C24: 23600.409 | D24: 0 | E24: 29844.624 | F24: 0 | G24: 9727.0556 | H24: 0 | I24: 44358.55 | J24: 38176.231 | K24: 2504.7641 | L24: 30810.619 | M24: 27446.956 | N24: 70876.611 | O24: 2387.1885 | P24: 33814.524 | Q24: 33029.622 | R24: 1226.6657 | S24: 726.36945 | T24: 10410.352 | U24: 11570.18 | V24: 11834.755 | W24: 2667.7183 | X24: 14744.306 | Y24: 62565.553 | Z24: 80103.406 | AA24: 0 | AB24: 0 | AC24: 0 | AD24: 2767.2949 | AE24: 8355.2488 | AF24: 0 | AG24: 10537.282 | AH24: 14650.159 | AI24: 0 | AJ24: 18377.534 | AK24: 0 | AL24: 9794.2502 | AM24: 0 | AN24: 26042.093 | AO24: 29488.806 | AP24: 2183.2407 | AQ24: 21494.697 | AR24: 20341.845 | AS24: 62966.218 | AT24: 2227.4474 | AU24: 40925.319 | AV24: 25631.27 | AW24: 1614.8396 | AX24: 839.00988 | AY24: 89222.802 | AZ24: 99790.039
A25: Pine Pulpwood | B25: 0 | C25: 9481.8658 | D25: 0 | E25: 15776.841 | F25: 0 | G25: 7113.8146 | H25: 0 | I25: 13492.006 | J25: 15248.126 | K25: 1097.3081 | L25: 11232.778 | M25: 8778.7163 | N25: 29702.46 | O25: 807.33567 | P25: 12071.431 | Q25: 11571.224 | R25: 515.13311 | S25: 238.41994 | T25: 3621.9893 | U25: 5620.7235 | V25: 4606.1173 | W25: 1203.9644 | X25: 7128.2433 | Y25: 24597.548 | Z25: 58255.623 | AA25: 0 | AB25: 0 | AC25: 0 | AD25: 2524.9565 | AE25: 7573.2416 | AF25: 0 | AG25: 3454.1396 | AH25: 8452.119 | AI25: 0 | AJ25: 20334.791 | AK25: 0 | AL25: 3979.6706 | AM25: 0 | AN25: 19020.547 | AO25: 16298.475 | AP25: 471.64672 | AQ25: 7835.7517 | AR25: 5188.7612 | AS25: 22286.18 | AT25: 509.979 | AU25: 8802.2842 | AV25: 9831.6612 | AW25: 382.2881 | AX25: 161.81733 | AY25: 27428.353 | AZ25: 26373.389
A26: HW Saw Timber | B26: 0 | C26: 335.78893 | D26: 0 | E26: 569.44043 | F26: 0 | G26: 72.061585 | H26: 0 | I26: 252.34545 | J26: 52.68087 | K26: 9.5890075 | L26: 21.766297 | M26: 203.87142 | N26: 538.59126 | O26: 20.243075 | P26: 335.95217 | Q26: 32.964104 | R26: 2.480963 | S26: 0 | T26: 58.357762 | U26: 0 | V26: 47.936062 | W26: 0.57452828 | X26: 3.2208712 | Y26: 4.7674258 | Z26: 0 | AA26: 0 | AB26: 0 | AC26: 0 | AD26: 0 | AE26: 0 | AF26: 0 | AG26: 0 | AH26: 0 | AI26: 0 | AJ26: 0.9684287 | AK26: 0 | AL26: 3.5958789 | AM26: 0 | AN26: 19.058427 | AO26: 0 | AP26: 0 | AQ26: 0 | AR26: 14.801522 | AS26: 26.536905 | AT26: 0 | AU26: 0 | AV26: 163.21766 | AW26: 12.046995 | AX26: 4.8121867 | AY26: 646.75535 | AZ26: 0
A27: HW Pulpwood | B27: 0 | C27: 1875.9037 | D27: 0 | E27: 4162.076 | F27: 0 | G27: 529.16745 | H27: 0 | I27: 1947.0905 | J27: 662.14328 | K27: 120.31581 | L27: 258.96642 | M27: 473.47431 | N27: 3577.7072 | O27: 28.500461 | P27: 487.6436 | Q27: 100.49091 | R27: 43.484844 | S27: 0 | T27: 113.8638 | U27: 0 | V27: 598.2232 | W27: 12.967975 | X27: 72.69995 | Y27: 107.60803 | Z27: 0 | AA27: 0 | AB27: 0 | AC27: 0 | AD27: 0 | AE27: 0 | AF27: 0 | AG27: 0 | AH27: 0 | AI27: 0 | AJ27: 4.3585918 | AK27: 0 | AL27: 15.825895 | AM27: 0 | AN27: 259.91388 | AO27: 89.538024 | AP27: 0 | AQ27: 0 | AR27: 182.15142 | AS27: 380.13809 | AT27: 0 | AU27: 0 | AV27: 277.65106 | AW27: 20.493254 | AX27: 8.186055 | AY27: 1045.2601 | AZ27: 0
A28: First Thin Volume (tons) | B28: =SUM(B29:B32) -> 0 | C28: =SUM(C29:C32) -> 9959.3071 | D28: =SUM(D29:D32) -> 4751.7809 | E28: =SUM(E29:E32) -> 2563.1304 | F28: =SUM(F29:F32) -> 12686.801 | G28: =SUM(G29:G32) -> 5130.8191 | H28: =SUM(H29:H32) -> 0 | I28: =SUM(I29:I32) -> 0 | ... AZ28: =SUM(AZ29:AZ32) -> 20622.732
A29: Pine Large Saw Timber | B29: 0 | C29: 0 | D29: 0 | E29: 0 | F29: 2.461212 | G29: 0 | H29: 0 | I29: 0 | J29: 0 | K29: 0 | L29: 0 | M29: 0 | N29: 0 | O29: 0 | P29: 0 | Q29: 0 | R29: 0 | S29: 0 | T29: 0 | U29: 0 | V29: 0 | W29: 0 | X29: 0 | Y29: 0 | Z29: 0 | AA29: 0 | AB29: 0 | AC29: 0 | AD29: 0 | AE29: 0 | AF29: 0 | AG29: 0 | AH29: 0 | AI29: 0 | AJ29: 0 | AK29: 0 | AL29: 0 | AM29: 0 | AN29: 0 | AO29: 0 | AP29: 0 | AQ29: 0 | AR29: 0 | AS29: 0 | AT29: 0 | AU29: 0 | AV29: 0 | AW29: 0 | AX29: 0 | AY29: 0 | AZ29: 0
A30: Pine Saw Timber | B30: 0 | C30: 14.537703 | D30: 22.062283 | E30: 19.640917 | F30: 0 | G30: 7.3932 | H30: 0 | I30: 0 | J30: 0 | K30: 0 | L30: 0 | M30: 0 | N30: 0 | O30: 0 | P30: 0 | Q30: 0 | R30: 0 | S30: 0 | T30: 0 | U30: 0 | V30: 0 | W30: 0 | X30: 0 | Y30: 0 | Z30: 0 | AA30: 0 | AB30: 0 | AC30: 0 | AD30: 0 | AE30: 0 | AF30: 0 | AG30: 0 | AH30: 0 | AI30: 0 | AJ30: 0 | AK30: 0 | AL30: 0 | AM30: 0 | AN30: 0 | AO30: 0 | AP30: 0 | AQ30: 0 | AR30: 0 | AS30: 0 | AT30: 0 | AU30: 0 | AV30: 0 | AW30: 0 | AX30: 0 | AY30: 0 | AZ30: 0
A31: Pine Chip-N-Saw | B31: 0 | C31: 4579.5133 | D31: 1552.6814 | E31: 529.89649 | F31: 2057.1727 | G31: 363.84031 | H31: 0 | I31: 0 | J31: 7915.9029 | K31: 17200.412 | L31: 3946.5599 | M31: 0 | N31: 1382.2862 | O31: 2401.1385 | P31: 11696.285 | Q31: 0 | R31: 935.70432 | S31: 3517.1739 | T31: 0 | U31: 10507.889 | V31: 0 | W31: 541.63643 | X31: 0 | Y31: 10882.776 | Z31: 18852.184 | AA31: 1.373302 | AB31: 7156.4577 | AC31: 5644.838 | AD31: 10696.078 | AE31: 487.30812 | AF31: 2398.3382 | AG31: 16737.544 | AH31: 24.656528 | AI31: 31.857541 | AJ31: 2125.64 | AK31: 2714.6567 | AL31: 837.73436 | AM31: 602.504 | AN31: 2682.092 | AO31: 1533.6055 | AP31: 11368.632 | AQ31: 0 | AR31: 0 | AS31: 0 | AT31: 803.65515 | AU31: 4758.2287 | AV31: 0 | AW31: 308.98801 | AX31: 1595.8265 | AY31: 0 | AZ31: 10617.111
A32: Pine Pulpwood | B32: 0 | C32: 5365.256 | D32: 3177.0371 | E32: 2013.593 | F32: 10627.167 | G32: 4759.5856 | H32: 0 | I32: 0 | J32: 16262.987 | K32: 35342.669 | L32: 9140.868 | M32: 0 | N32: 9038.3202 | O32: 20243.227 | P32: 14689.298 | Q32: 0 | R32: 4135.8166 | S32: 5850.2918 | T32: 9.595031 | U32: 9726.6187 | V32: 0 | W32: 2402.3859 | X32: 0 | Y32: 12550.853 | Z32: 14545.626 | AA32: 606.47786 | AB32: 6516.5588 | AC32: 7770.7774 | AD32: 22812.89 | AE32: 865.03332 | AF32: 13217.409 | AG32: 12459.355 | AH32: 421.5625 | AI32: 257.87178 | AJ32: 3946.0815 | AK32: 5115.8001 | AL32: 4221.1038 | AM32: 1100.5988 | AN32: 6145.7388 | AO32: 22618.262 | AP32: 27013.856 | AQ32: 1177.0135 | AR32: 0 | AS32: 0 | AT32: 1468.0432 | AU32: 4538.6871 | AV32: 0 | AW32: 2899.0795 | AX32: 4752.4045 | AY32: 9.595031 | AZ32: 10005.621
A33: Second Thin Volume (tons) | B33: =SUM(B34:B37) -> 0 | C33: =SUM(C34:C37) -> 0 | D33: =SUM(D34:D37) -> 0 | E33: =SUM(E34:E37) -> 4273.6633 | F33: =SUM(F34:F37) -> 7058.233 | G33: =SUM(G34:G37) -> 299.8344 | H33: =SUM(H34:H37) -> 2857.348 | I33: =SUM(I34:I37) -> 2231.7607 | ... AZ33: =SUM(AZ34:AZ37) -> 9094.3261
A34: Pine Large Saw Timber | B34: 0 | C34: 0 | D34: 0 | E34: 9.91116 | F34: 160.34929 | G34: 0 | H34: 0 | I34: 0 | J34: 0 | K34: 0 | L34: 0 | M34: 23.667807 | N34: 0 | O34: 0 | P34: 0 | Q34: 0 | R34: 692.74119 | S34: 264.97248 | T34: 0 | U34: 9.792384 | V34: 0 | W34: 14.94796 | X34: 0 | Y34: 23.949768 | Z34: 11.677051 | AA34: 100.29704 | AB34: 28.597095 | AC34: 0 | AD34: 5.193252 | AE34: 4.325148 | AF34: 85.851185 | AG34: 47.985616 | AH34: 0 | AI34: 0 | AJ34: 0 | AK34: 77.506328 | AL34: 0 | AM34: 6.169023 | AN34: 0 | AO34: 0 | AP34: 0 | AQ34: 3.992679 | AR34: 16.884585 | AS34: 0 | AT34: 0 | AU34: 22.178584 | AV34: 0 | AW34: 0 | AX34: 0 | AY34: 0 | AZ34: 4.507696
A35: Pine Saw Timber | B35: 0 | C35: 0 | D35: 0 | E35: 4.493424 | F35: 0 | G35: 1.007624 | H35: 11.273856 | I35: 107.02169 | J35: 76.995358 | K35: 0.488628 | L35: 0 | M35: 0.208408 | N35: 0 | O35: 0 | P35: 409.01862 | Q35: 600.02363 | R35: 363.34979 | S35: 0 | T35: 0 | U35: 0 | V35: 0 | W35: 4.665245 | X35: 0 | Y35: 0 | Z35: 0 | AA35: 0 | AB35: 0 | AC35: 0 | AD35: 0.544752 | AE35: 0 | AF35: 0 | AG35: 144.82022 | AH35: 0 | AI35: 125.28598 | AJ35: 22.509432 | AK35: 0.614592 | AL35: 0 | AM35: 0 | AN35: 266.62817 | AO35: 0 | AP35: 0 | AQ35: 0 | AR35: 0 | AS35: 0 | AT35: 0 | AU35: 0 | AV35: 0 | AW35: 0 | AX35: 0 | AY35: 0 | AZ35: 4.665245
A36: Pine Chip-N-Saw | B36: 0 | C36: 0 | D36: 0 | E36: 2785.7437 | F36: 5157.3315 | G36: 224.12027 | H36: 2250.1516 | I36: 1404.5737 | J36: 6374.8437 | K36: 82.369274 | L36: 0 | M36: 1370.1911 | N36: 0 | O36: 0 | P36: 9384.4496 | Q36: 11640.975 | R36: 24419.809 | S36: 3747.0585 | T36: 1343.6328 | U36: 9341.9275 | V36: 3625.8462 | W36: 3587.4547 | X36: 0 | Y36: 3579.6525 | Z36: 2838.7443 | AA36: 11504.049 | AB36: 6388.9731 | AC36: 0 | AD36: 1344.4835 | AE36: 494.81291 | AF36: 20556.692 | AG36: 28693.698 | AH36: 0 | AI36: 9875.0998 | AJ36: 10123.344 | AK36: 19253.194 | AL36: 955.82531 | AM36: 5823.6615 | AN36: 22156.589 | AO36: 99.4798 | AP36: 2857.5425 | AQ36: 966.80018 | AR36: 6223.7518 | AS36: 3063.4569 | AT36: 2613.5894 | AU36: 12730.194 | AV36: 0 | AW36: 0 | AX36: 0 | AY36: 0 | AZ36: 7070.3958
A37: Pine Pulpwood | B37: 0 | C37: 0 | D37: 0 | E37: 1473.515 | F37: 1740.5522 | G37: 74.706503 | H37: 595.92262 | I37: 720.16529 | J37: 2909.6463 | K37: 46.933218 | L37: 0 | M37: 889.26783 | N37: 0 | O37: 0 | P37: 5708.8764 | Q37: 6305.9264 | R37: 12083.553 | S37: 1888.2425 | T37: 372.66028 | U37: 2312.2745 | V37: 732.86558 | W37: 811.45916 | X37: 0 | Y37: 819.05483 | Z37: 616.30091 | AA37: 2246.0595 | AB37: 1340.8283 | AC37: 0 | AD37: 315.77689 | AE37: 96.422841 | AF37: 4428.7775 | AG37: 5953.1709 | AH37: 0 | AI37: 1933.2069 | AJ37: 2906.0738 | AK37: 5086.212 | AL37: 318.21345 | AM37: 2110.4253 | AN37: 4586.2049 | AO37: 39.223271 | AP37: 970.29929 | AQ37: 220.55397 | AR37: 1526.8739 | AS37: 1110.8082 | AT37: 858.24279 | AU37: 3578.8941 | AV37: 0 | AW37: 0 | AX37: 0 | AY37: 0 | AZ37: 2014.7574
A38: Selection Thinning Volume (tons) | B38: =SUM(B39:B42) -> 0 | C38: =SUM(C39:C42) -> 0 | D38: =SUM(D39:D42) -> 0 | E38: =SUM(E39:E42) -> 0 | F38: =SUM(F39:F42) -> 0 | G38: =SUM(G39:G42) -> 0 | H38: =SUM(H39:H42) -> 0 | I38: =SUM(I39:I42) -> 0 | ... AZ38: =SUM(AZ39:AZ42) -> 0
A39: Pine Large Saw Timber | B39: 0 | C39: 0 | D39: 0 | E39: 0 | F39: 0 | G39: 0 | H39: 0 | I39: 0 | J39: 0 | K39: 0 | L39: 0 | M39: 0 | N39: 0 | O39: 0 | P39: 0 | Q39: 0 | R39: 0 | S39: 0 | T39: 0 | U39: 0 | V39: 0 | W39: 0 | X39: 0 | Y39: 0 | Z39: 0 | AA39: 0 | AB39: 0 | AC39: 0 | AD39: 0 | AE39: 0 | AF39: 0 | AG39: 0 | AH39: 0 | AI39: 0 | AJ39: 0 | AK39: 0 | AL39: 0 | AM39: 0 | AN39: 0 | AO39: 0 | AP39: 0 | AQ39: 0 | AR39: 0 | AS39: 0 | AT39: 0 | AU39: 0 | AV39: 0 | AW39: 0 | AX39: 0 | AY39: 0 | AZ39: 0
A40: Pine Saw Timber | B40: 0 | C40: 0 | D40: 0 | E40: 0 | F40: 0 | G40: 0 | H40: 0 | I40: 0 | J40: 0 | K40: 0 | L40: 0 | M40: 0 | N40: 0 | O40: 0 | P40: 0 | Q40: 0 | R40: 0 | S40: 0 | T40: 0 | U40: 0 | V40: 0 | W40: 0 | X40: 0 | Y40: 0 | Z40: 0 | AA40: 0 | AB40: 0 | AC40: 0 | AD40: 0 | AE40: 0 | AF40: 0 | AG40: 0 | AH40: 0 | AI40: 0 | AJ40: 0 | AK40: 0 | AL40: 0 | AM40: 0 | AN40: 0 | AO40: 0 | AP40: 0 | AQ40: 0 | AR40: 0 | AS40: 0 | AT40: 0 | AU40: 0 | AV40: 0 | AW40: 0 | AX40: 0 | AY40: 0 | AZ40: 0
A41: Pine Chip-N-Saw | B41: 0 | C41: 0 | D41: 0 | E41: 0 | F41: 0 | G41: 0 | H41: 0 | I41: 0 | J41: 0 | K41: 0 | L41: 0 | M41: 0 | N41: 0 | O41: 0 | P41: 0 | Q41: 0 | R41: 0 | S41: 0 | T41: 0 | U41: 0 | V41: 0 | W41: 0 | X41: 0 | Y41: 0 | Z41: 0 | AA41: 0 | AB41: 0 | AC41: 0 | AD41: 0 | AE41: 0 | AF41: 0 | AG41: 0 | AH41: 0 | AI41: 0 | AJ41: 0 | AK41: 0 | AL41: 0 | AM41: 0 | AN41: 0 | AO41: 0 | AP41: 0 | AQ41: 0 | AR41: 0 | AS41: 0 | AT41: 0 | AU41: 0 | AV41: 0 | AW41: 0 | AX41: 0 | AY41: 0 | AZ41: 0
A42: Pine Pulpwood | B42: 0 | C42: 0 | D42: 0 | E42: 0 | F42: 0 | G42: 0 | H42: 0 | I42: 0 | J42: 0 | K42: 0 | L42: 0 | M42: 0 | N42: 0 | O42: 0 | P42: 0 | Q42: 0 | R42: 0 | S42: 0 | T42: 0 | U42: 0 | V42: 0 | W42: 0 | X42: 0 | Y42: 0 | Z42: 0 | AA42: 0 | AB42: 0 | AC42: 0 | AD42: 0 | AE42: 0 | AF42: 0 | AG42: 0 | AH42: 0 | AI42: 0 | AJ42: 0 | AK42: 0 | AL42: 0 | AM42: 0 | AN42: 0 | AO42: 0 | AP42: 0 | AQ42: 0 | AR42: 0 | AS42: 0 | AT42: 0 | AU42: 0 | AV42: 0 | AW42: 0 | AX42: 0 | AY42: 0 | AZ42: 0
A44: Total Revenue | B44: 0 | C44: 777965.22 | D44: 183259.13 | E44: 881229.74 | F44: 303369.61 | G44: 431851.52 | H44: 187667.95 | I44: 1151060.5 | J44: 1513224 | K44: 684956.39 | L44: 1102075.5 | M44: 1106970.5 | N44: 2603399.7 | O44: 371585.05 | P44: 1790512.6 | Q44: 2099007.9 | R44: 748997.02 | S44: 315949.93 | T44: 503286.28 | U44: 924970.57 | V44: 576046.58 | W44: 402329.34 | X44: 1252673.8 | Y44: 2769440.7 | Z44: 5095858.5 | AA44: 324450.63 | AB44: 442688.5 | AC44: 310928.8 | AD44: 599817.1 | AE44: 685996.16 | AF44: 641412.54 | AG44: 1511921.4 | AH44: 648222.08 | AI44: 383377.36 | AJ44: 1547252 | AK44: 592139.1 | AL44: 475498.04 | AM44: 291326.36 | AN44: 2231419.6 | AO44: 2581923.3 | AP44: 581467.47 | AQ44: 1294770.1 | AR44: 1311047.7 | AS44: 2609576.2 | AT44: 326826.46 | AU44: 1751583.2 | AV44: 2232201.8 | AW44: 194370.58 | AX44: 210258.66 | AY44: 2908072.4 | AZ44: 3007619.9
A45: Total Removals | B45: 0 | C45: 643620.23 | D45: 48914.117 | E45: 746884.7 | F45: 169024.55 | G45: 297506.43 | H45: 53322.828 | I45: 1016715.4 | J45: 1378878.8 | K45: 550611.19 | L45: 967730.29 | M45: 972625.2 | N45: 2469054.4 | O45: 237239.74 | P45: 1656167.2 | Q45: 1964662.6 | R45: 614651.63 | S45: 181604.51 | T45: 368940.83 | U45: 790625.1 | V45: 441701.08 | W45: 267983.81 | X45: 1118328.2 | Y45: 2635095.1 | Z45: 4961512.9 | AA45: 190104.99 | AB45: 308342.85 | AC45: 176583.12 | AD45: 465471.39 | AE45: 551650.42 | AF45: 507066.78 | AG45: 1377575.6 | AH45: 513876.26 | AI45: 249031.51 | AJ45: 1412906.1 | AK45: 457793.2 | AL45: 341152.11 | AM45: 156980.4 | AN45: 2097073.6 | AO45: 2447577.3 | AP45: 447121.43 | AQ45: 1160424 | AR45: 1176701.6 | AS45: 2475230.1 | AT45: 192480.32 | AU45: 1617237 | AV45: 2097855.6 | AW45: 60024.361 | AX45: 75912.415 | AY45: 2773726.1 | AZ45: 2873273.6
A46: Clearcut Revenue | B46: 0 | C46: 524767.55 | D46: 0 | E46: 665400.28 | F46: 0 | G46: 258078.56 | H46: 0 | I46: 977383.49 | J46: 946214.46 | K46: 69220.067 | L46: 855415.01 | M46: 947769.02 | N46: 2385226.8 | O46: 78390.287 | P46: 1145467.8 | Q46: 1630925 | R46: 70756.85 | S46: 23764.111 | T46: 335427.68 | U46: 428506.01 | V46: 380991.54 | W46: 179696.76 | X46: 1118328.2 | Y46: 2321622.8 | Z46: 4432310 | AA46: 0 | AB46: 0 | AC46: 0 | AD46: 122985 | AE46: 527269.13 | AF46: 0 | AG46: 265082.96 | AH46: 510860.59 | AI46: 0 | AJ46: 1090838.3 | AK46: 0 | AL46: 277836.05 | AM46: 0 | AN46: 1444418 | AO46: 2282585.4 | AP46: 54705.2 | AQ46: 1139908.5 | AR46: 1054019.3 | AS46: 2406305.7 | AT46: 109306.92 | AU46: 1269020.3 | AV46: 2097855.6 | AW46: 43521.113 | AX46: 25374.334 | AY46: 2773692.8 | AZ46: 2547416.3
...

Sheet Output Graphs
A1: DISCOUNTED CASH FLOW ANALYSIS
A2: Output Graphs
A3: =CONCATENATE('Model Assumptions'!B2, " - ",'Model Assumptions'!B3 ) -> IWC - Boot Hill
A4: ='Model Assumptions'!B5 -> IWC - Boothill - HSM

Sheet Finance Per Unit
A1: DISCOUNTED CASH FLOW ANALYSIS
A2: Finance Per Unit
A3: =CONCATENATE('Model Assumptions'!B2, " - ",'Model Assumptions'!B3 ) -> IWC - Boot Hill
A4: ='Model Assumptions'!B5 -> IWC - Boothill - HSM
A6: Calendar Year >> | B6: ='Finance Report'!B6 -> Model Year 0 | C6: 2026 | D6: =C6+1 -> 2027 | E6: =D6+1 -> 2028 | F6: =E6+1 -> 2029 | G6: =F6+1 -> 2030 | H6: =G6+1 -> 2031 | I6: =H6+1 -> 2032 | J6: =I6+1 -> 2033 | K6: =J6+1 -> 2034 | ... AZ6: =AY6+1 -> 2075
A7: Model Discount Period >> | B7: 0 | C7: 1 | D7: =C7+1 -> 2 | E7: =D7+1 -> 3 | F7: =E7+1 -> 4 | G7: =F7+1 -> 5 | H7: =G7+1 -> 6 | I7: =H7+1 -> 7 | J7: =I7+1 -> 8 | K7: =J7+1 -> 9 | ... AZ7: =AY7+1 -> 50
A9: Total Acres | B9: 12404.89 | C9: 12404.89 | D9: 12404.89 | E9: 12404.89 | F9: 12404.89 | G9: 12404.89 | H9: 12404.89 | I9: 12404.89 | J9: 12404.89 | K9: 12404.89 | L9: 12404.89 | M9: 12404.89 | N9: 12404.89 | O9: 12404.89 | P9: 12404.89 | Q9: 12404.89 | R9: 12404.89 | S9: 12404.89 | T9: 12404.89 | U9: 12404.89 | V9: 12404.89 | W9: 12404.89 | X9: 12404.89 | Y9: 12404.89 | Z9: 12404.89 | AA9: 12404.89 | AB9: 12404.89 | AC9: 12404.89 | AD9: 12404.89 | AE9: 12404.89 | AF9: 12404.89 | AG9: 12404.89 | AH9: 12404.89 | AI9: 12404.89 | AJ9: 12404.89 | AK9: 12404.89 | AL9: 12404.89 | AM9: 12404.89 | AN9: 12404.89 | AO9: 12404.89 | AP9: 12404.89 | AQ9: 12404.89 | AR9: 12404.89 | AS9: 12404.89 | AT9: 12404.89 | AU9: 12404.89 | AV9: 12404.89 | AW9: 12404.89 | AX9: 12404.89 | AY9: 12404.89 | AZ9: 12404.89
A10: Productive Plantation Acres | B10: 8762.98 | C10: 8762.98 | D10: 8762.98 | E10: 8762.98 | F10: 8762.98 | G10: 8762.98 | H10: 8762.98 | I10: 8762.98 | J10: 8762.98 | K10: 8762.98 | L10: 8762.98 | M10: 8762.98 | N10: 8762.98 | O10: 8762.98 | P10: 8762.98 | Q10: 8762.98 | R10: 8762.98 | S10: 8762.98 | T10: 8762.98 | U10: 8762.98 | V10: 8762.98 | W10: 8762.98 | X10: 8762.98 | Y10: 8762.98 | Z10: 8762.98 | AA10: 8762.98 | AB10: 8762.98 | AC10: 8762.98 | AD10: 8762.98 | AE10: 8762.98 | AF10: 8762.98 | AG10: 8762.98 | AH10: 8762.98 | AI10: 8762.98 | AJ10: 8762.98 | AK10: 8762.98 | AL10: 8762.98 | AM10: 8762.98 | AN10: 8762.98 | AO10: 8762.98 | AP10: 8762.98 | AQ10: 8762.98 | AR10: 8762.98 | AS10: 8762.98 | AT10: 8762.98 | AU10: 8762.98 | AV10: 8762.98 | AW10: 8762.98 | AX10: 8762.98 | AY10: 8762.98 | AZ10: 8762.98
A11: Natural Convertible Acres | B11: 611.17 | C11: 611.17 | D11: 611.17 | E11: 611.17 | F11: 611.17 | G11: 611.17 | H11: 611.17 | I11: 611.17 | J11: 611.17 | K11: 611.17 | L11: 611.17 | M11: 611.17 | N11: 611.17 | O11: 611.17 | P11: 611.17 | Q11: 611.17 | R11: 611.17 | S11: 611.17 | T11: 611.17 | U11: 611.17 | V11: 611.17 | W11: 611.17 | X11: 611.17 | Y11: 611.17 | Z11: 611.17 | AA11: 611.17 | AB11: 611.17 | AC11: 611.17 | AD11: 611.17 | AE11: 611.17 | AF11: 611.17 | AG11: 611.17 | AH11: 611.17 | AI11: 611.17 | AJ11: 611.17 | AK11: 611.17 | AL11: 611.17 | AM11: 611.17 | AN11: 611.17 | AO11: 611.17 | AP11: 611.17 | AQ11: 611.17 | AR11: 611.17 | AS11: 611.17 | AT11: 611.17 | AU11: 611.17 | AV11: 611.17 | AW11: 611.17 | AX11: 611.17 | AY11: 611.17 | AZ11: 611.17
A12: Non-Converitble Acres | B12: 3030.74 | C12: 3030.74 | D12: 3030.74 | E12: 3030.74 | F12: 3030.74 | G12: 3030.74 | H12: 3030.74 | I12: 3030.74 | J12: 3030.74 | K12: 3030.74 | L12: 3030.74 | M12: 3030.74 | N12: 3030.74 | O12: 3030.74 | P12: 3030.74 | Q12: 3030.74 | R12: 3030.74 | S12: 3030.74 | T12: 3030.74 | U12: 3030.74 | V12: 3030.74 | W12: 3030.74 | X12: 3030.74 | Y12: 3030.74 | Z12: 3030.74 | AA12: 3030.74 | AB12: 3030.74 | AC12: 3030.74 | AD12: 3030.74 | AE12: 3030.74 | AF12: 3030.74 | AG12: 3030.74 | AH12: 3030.74 | AI12: 3030.74 | AJ12: 3030.74 | AK12: 3030.74 | AL12: 3030.74 | AM12: 3030.74 | AN12: 3030.74 | AO12: 3030.74 | AP12: 3030.74 | AQ12: 3030.74 | AR12: 3030.74 | AS12: 3030.74 | AT12: 3030.74 | AU12: 3030.74 | AV12: 3030.74 | AW12: 3030.74 | AX12: 3030.74 | AY12: 3030.74 | AZ12: 3030.74
A14: Total Revenue (Per Harvest Acre)
A15: Total Removals | B15: =IF('Finance Report'!B$19=0,0,'Finance Report'!B45/'Finance Report'!B$19) -> 0 | C15: =IF('Finance Report'!C$19=0,0,'Finance Report'!C45/'Finance Report'!C$19) -> 699.61762 | D15: =IF('Finance Report'!D$19=0,0,'Finance Report'!D45/'Finance Report'!D$19) -> 252.99533 | E15: =IF('Finance Report'!E$19=0,0,'Finance Report'!E45/'Finance Report'!E$19) -> 1068.2289 | F15: =IF('Finance Report'!F$19=0,0,'Finance Report'!F45/'Finance Report'!F$19) -> 293.0384 | G15: =IF('Finance Report'!G$19=0,0,'Finance Report'!G45/'Finance Report'!G$19) -> 705.47634 | H15: =IF('Finance Report'!H$19=0,0,'Finance Report'!H45/'Finance Report'!H$19) -> 445.54502 | I15: =IF('Finance Report'!I$19=0,0,'Finance Report'!I45/'Finance Report'!I$19) -> 1575.762 | ... AZ15: =IF('Finance Report'!AZ$19=0,0,'Finance Report'!AZ45/'Finance Report'!AZ$19) -> 1292.7745
A16: Clearcut Revenue | B16: =IF('Finance Report'!B$46=0,0,'Finance Report'!B46/'Harvest Report'!B$55) -> 0 | C16: =IF('Finance Report'!C$46=0,0,'Finance Report'!C46/'Harvest Report'!C$55) -> 1393.3608 | D16: =IF('Finance Report'!D$46=0,0,'Finance Report'!D46/'Harvest Report'!D$55) -> 0 | E16: =IF('Finance Report'!E$46=0,0,'Finance Report'!E46/'Harvest Report'!E$55) -> 1465.8964 | F16: =IF('Finance Report'!F$46=0,0,'Finance Report'!F46/'Harvest Report'!F$55) -> 0 | G16: =IF('Finance Report'!G$46=0,0,'Finance Report'!G46/'Harvest Report'!G$55) -> 1210.6134 | H16: =IF('Finance Report'!H$46=0,0,'Finance Report'!H46/'Harvest Report'!H$55) -> 0 | I16: =IF('Finance Report'!I$46=0,0,'Finance Report'!I46/'Harvest Report'!I$55) -> 1741.9948 | ... AZ16: =IF('Finance Report'!AZ$46=0,0,'Finance Report'!AZ46/'Harvest Report'!AZ$55) -> 1698.2775
A17: First Thin Revenue | B17: =IF('Finance Report'!B$47=0,0,'Finance Report'!B47/'Harvest Report'!B$77) -> 0 | C17: =IF('Finance Report'!C$47=0,0,'Finance Report'!C47/'Harvest Report'!C$77) -> 218.74458 | D17: =IF('Finance Report'!D$47=0,0,'Finance Report'!D47/'Harvest Report'!D$77) -> 252.99533 | E17: =IF('Finance Report'!E$47=0,0,'Finance Report'!E47/'Harvest Report'!E$77) -> 233.32858 | F17: =IF('Finance Report'!F$47=0,0,'Finance Report'!F47/'Harvest Report'!F$77) -> 200.41521 | G17: =IF('Finance Report'!G$47=0,0,'Finance Report'!G47/'Harvest Report'!G$77) -> 169.95897 | H17: =IF('Finance Report'!H$47=0,0,'Finance Report'!H47/'Harvest Report'!H$77) -> 0 | I17: =IF('Finance Report'!I$47=0,0,'Finance Report'!I47/'Harvest Report'!I$77) -> 0 | ... AZ17: =IF('Finance Report'!AZ$47=0,0,'Finance Report'!AZ47/'Harvest Report'!AZ$77) -> 437.43083
A18: Second Thin Revenue | B18: =IF('Finance Report'!B$48=0,0,'Finance Report'!B48/'Harvest Report'!B$86) -> 0 | C18: =IF('Finance Report'!C$48=0,0,'Finance Report'!C48/'Harvest Report'!C$86) -> 0 | D18: =IF('Finance Report'!D$48=0,0,'Finance Report'!D48/'Harvest Report'!D$86) -> 0 | E18: =IF('Finance Report'!E$48=0,0,'Finance Report'!E48/'Harvest Report'!E$86) -> 395.75409 | F18: =IF('Finance Report'!F$48=0,0,'Finance Report'!F48/'Harvest Report'!F$86) -> 566.21496 | G18: =IF('Finance Report'!G$48=0,0,'Finance Report'!G48/'Harvest Report'!G$86) -> 678.41821 | H18: =IF('Finance Report'!H$48=0,0,'Finance Report'!H48/'Harvest Report'!H$86) -> 445.54502 | I18: =IF('Finance Report'!I$48=0,0,'Finance Report'!I48/'Harvest Report'!I$86) -> 467.40188 | ... AZ18: =IF('Finance Report'!AZ$48=0,0,'Finance Report'!AZ48/'Harvest Report'!AZ$86) -> 474.19402
A19: Selection Thin Revenue | B19: =IF('Finance Report'!B$49=0,0,'Finance Report'!B49/'Harvest Report'!B$107) -> 0 | C19: =IF('Finance Report'!C$49=0,0,'Finance Report'!C49/'Harvest Report'!C$107) -> 0 | D19: =IF('Finance Report'!D$49=0,0,'Finance Report'!D49/'Harvest Report'!D$107) -> 0 | E19: =IF('Finance Report'!E$49=0,0,'Finance Report'!E49/'Harvest Report'!E$107) -> 0 | F19: =IF('Finance Report'!F$49=0,0,'Finance Report'!F49/'Harvest Report'!F$107) -> 0 | G19: =IF('Finance Report'!G$49=0,0,'Finance Report'!G49/'Harvest Report'!G$107) -> 0 | H19: =IF('Finance Report'!H$49=0,0,'Finance Report'!H49/'Harvest Report'!H$107) -> 0 | I19: =IF('Finance Report'!I$49=0,0,'Finance Report'!I49/'Harvest Report'!I$107) -> 0 | ... AZ19: =IF('Finance Report'!AZ$49=0,0,'Finance Report'!AZ49/'Harvest Report'!AZ$107) -> 0
A20: Hunt Lease (Per Acre) | B20: ='Finance Report'!B50/'Finance Report'!B$9 -> 0 | C20: ='Finance Report'!C50/'Finance Report'!C$9 -> 10.830002 | D20: ='Finance Report'!D50/'Finance Report'!D$9 -> 10.830004 | E20: ='Finance Report'!E50/'Finance Report'!E$9 -> 10.830006 | F20: ='Finance Report'!F50/'Finance Report'!F$9 -> 10.830009 | G20: ='Finance Report'!G50/'Finance Report'!G$9 -> 10.830011 | H20: ='Finance Report'!H50/'Finance Report'!H$9 -> 10.830013 | I20: ='Finance Report'!I50/'Finance Report'!I$9 -> 10.830015 | ... AZ20: ='Finance Report'!AZ50/'Finance Report'!AZ$9 -> 10.830108
A21: Miscellanous Revenue (Per Acre) | B21: ='Finance Report'!B51/'Finance Report'!B$9 -> 0 | C21: ='Finance Report'!C51/'Finance Report'!C$9 -> 0 | D21: ='Finance Report'!D51/'Finance Report'!D$9 -> 0 | E21: ='Finance Report'!E51/'Finance Report'!E$9 -> 0 | F21: ='Finance Report'!F51/'Finance Report'!F$9 -> 0 | G21: ='Finance Report'!G51/'Finance Report'!G$9 -> 0 | H21: ='Finance Report'!H51/'Finance Report'!H$9 -> 0 | I21: ='Finance Report'!I51/'Finance Report'!I$9 -> 0 | ... AZ21: ='Finance Report'!AZ51/'Finance Report'!AZ$9 -> 0
A23: Total Costs
A24: Overhead - Fixed
A25: Lease Fees | B25: ='Finance Report'!B55/'Finance Report'!B$9 -> 0 | C25: ='Finance Report'!C55/'Finance Report'!C$9 -> #VALUE! | D25: ='Finance Report'!D55/'Finance Report'!D$9 -> 0 | E25: ='Finance Report'!E55/'Finance Report'!E$9 -> 0 | F25: ='Finance Report'!F55/'Finance Report'!F$9 -> 0 | G25: ='Finance Report'!G55/'Finance Report'!G$9 -> 0 | H25: ='Finance Report'!H55/'Finance Report'!H$9 -> 0 | I25: ='Finance Report'!I55/'Finance Report'!I$9 -> 0 | ... AZ25: ='Finance Report'!AZ55/'Finance Report'!AZ$9 -> 0
A26: Management | B26: ='Finance Report'!B56/'Finance Report'!B$9 -> 0 | C26: ='Finance Report'!C56/'Finance Report'!C$9 -> 8.0000016 | D26: ='Finance Report'!D56/'Finance Report'!D$9 -> 8.0000032 | E26: ='Finance Report'!E56/'Finance Report'!E$9 -> 8.0000048 | F26: ='Finance Report'!F56/'Finance Report'!F$9 -> 8.0000064 | G26: ='Finance Report'!G56/'Finance Report'!G$9 -> 8.000008 | H26: ='Finance Report'!H56/'Finance Report'!H$9 -> 8.0000096 | I26: ='Finance Report'!I56/'Finance Report'!I$9 -> 8.0000112 | ... AZ26: ='Finance Report'!AZ56/'Finance Report'!AZ$9 -> 8.00008
A27: Taxes | B27: ='Finance Report'!B57/'Finance Report'!B$9 -> 0 | C27: ='Finance Report'!C57/'Finance Report'!C$9 -> 2.5100005 | D27: ='Finance Report'!D57/'Finance Report'!D$9 -> 2.510001 | E27: ='Finance Report'!E57/'Finance Report'!E$9 -> 2.5100015 | F27: ='Finance Report'!F57/'Finance Report'!F$9 -> 2.510002 | G27: ='Finance Report'!G57/'Finance Report'!G$9 -> 2.5100025 | H27: ='Finance Report'!H57/'Finance Report'!H$9 -> 2.510003 | I27: ='Finance Report'!I57/'Finance Report'!I$9 -> 2.5100035 | ... AZ27: ='Finance Report'!AZ57/'Finance Report'!AZ$9 -> 2.5100251
A28: Roads | B28: ='Finance Report'!B58/'Finance Report'!B$9 -> 0 | C28: ='Finance Report'!C58/'Finance Report'!C$9 -> 3.5000007 | D28: ='Finance Report'!D58/'Finance Report'!D$9 -> 3.5000014 | E28: ='Finance Report'!E58/'Finance Report'!E$9 -> 3.5000021 | F28: ='Finance Report'!F58/'Finance Report'!F$9 -> 3.5000028 | G28: ='Finance Report'!G58/'Finance Report'!G$9 -> 3.5000035 | H28: ='Finance Report'!H58/'Finance Report'!H$9 -> 3.5000042 | I28: ='Finance Report'!I58/'Finance Report'!I$9 -> 3.5000049 | ... AZ28: ='Finance Report'!AZ58/'Finance Report'!AZ$9 -> 3.500035
A29: Misc. | B29: ='Finance Report'!B59/'Finance Report'!B$9 -> 0 | C29: ='Finance Report'!C59/'Finance Report'!C$9 -> 0.35000007 | D29: ='Finance Report'!D59/'Finance Report'!D$9 -> 0.35000014 | E29: ='Finance Report'!E59/'Finance Report'!E$9 -> 0.35000021 | F29: ='Finance Report'!F59/'Finance Report'!F$9 -> 0.35000028 | G29: ='Finance Report'!G59/'Finance Report'!G$9 -> 0.35000035 | H29: ='Finance Report'!H59/'Finance Report'!H$9 -> 0.35000042 | I29: ='Finance Report'!I59/'Finance Report'!I$9 -> 0.35000049 | ... AZ29: ='Finance Report'!AZ59/'Finance Report'!AZ$9 -> 0.3500035
A30: Silviculture
A31: SitePrep | B31: =IF('Activity Report'!B25=0,0,'Finance Report'!B61/'Activity Report'!B25) -> 0 | C31: =IF('Activity Report'!C25=0,0,'Finance Report'!C61/'Activity Report'!C25) -> 122.50002 | D31: =IF('Activity Report'!D25=0,0,'Finance Report'!D61/'Activity Report'!D25) -> 122.50005 | E31: =IF('Activity Report'!E25=0,0,'Finance Report'!E61/'Activity Report'!E25) -> 0 | F31: =IF('Activity Report'!F25=0,0,'Finance Report'!F61/'Activity Report'!F25) -> 122.5001 | G31: =IF('Activity Report'!G25=0,0,'Finance Report'!G61/'Activity Report'!G25) -> 0 | H31: =IF('Activity Report'!H25=0,0,'Finance Report'!H61/'Activity Report'!H25) -> 122.50015 | I31: =IF('Activity Report'!I25=0,0,'Finance Report'!I61/'Activity Report'!I25) -> 0 | ... AZ31: =IF('Activity Report'!AZ25=0,0,'Finance Report'!AZ61/'Activity Report'!AZ25) -> 122.50122
A32: Planting | B32: =IF('Activity Report'!B26=0,0,'Finance Report'!B62/'Activity Report'!B26) -> 0 | C32: =IF('Activity Report'!C26=0,0,'Finance Report'!C62/'Activity Report'!C26) -> 0 | D32: =IF('Activity Report'!D26=0,0,'Finance Report'!D62/'Activity Report'!D26) -> 120.40005 | E32: =IF('Activity Report'!E26=0,0,'Finance Report'!E62/'Activity Report'!E26) -> 120.40007 | F32: =IF('Activity Report'!F26=0,0,'Finance Report'!F62/'Activity Report'!F26) -> 0 | G32: =IF('Activity Report'!G26=0,0,'Finance Report'!G62/'Activity Report'!G26) -> 120.40012 | H32: =IF('Activity Report'!H26=0,0,'Finance Report'!H62/'Activity Report'!H26) -> 0 | I32: =IF('Activity Report'!I26=0,0,'Finance Report'!I62/'Activity Report'!I26) -> 120.40017 | ... AZ32: =IF('Activity Report'!AZ26=0,0,'Finance Report'!AZ62/'Activity Report'!AZ26) -> 120.40121
A33: Herb Weed Control | B33: =IF('Activity Report'!B27=0,0,'Finance Report'!B63/'Activity Report'!B27) -> 0 | C33: =IF('Activity Report'!C27=0,0,'Finance Report'!C63/'Activity Report'!C27) -> 0 | D33: =IF('Activity Report'!D27=0,0,'Finance Report'!D63/'Activity Report'!D27) -> 44.270009 | E33: =IF('Activity Report'!E27=0,0,'Finance Report'!E63/'Activity Report'!E27) -> 44.270013 | F33: =IF('Activity Report'!F27=0,0,'Finance Report'!F63/'Activity Report'!F27) -> 0 | G33: =IF('Activity Report'!G27=0,0,'Finance Report'!G63/'Activity Report'!G27) -> 44.270022 | H33: =IF('Activity Report'!H27=0,0,'Finance Report'!H63/'Activity Report'!H27) -> 0 | I33: =IF('Activity Report'!I27=0,0,'Finance Report'!I63/'Activity Report'!I27) -> 44.270031 | ... AZ33: =IF('Activity Report'!AZ27=0,0,'Finance Report'!AZ63/'Activity Report'!AZ27) -> 44.270226
A34: Fertilizer | B34: =IF('Activity Report'!B32=0,0,'Finance Report'!B64/'Activity Report'!B32) -> 0 | C34: =IF('Activity Report'!C32=0,0,'Finance Report'!C64/'Activity Report'!C32) -> 0 | D34: =IF('Activity Report'!D32=0,0,'Finance Report'!D64/'Activity Report'!D32) -> 160.00003 | E34: =IF('Activity Report'!E32=0,0,'Finance Report'!E64/'Activity Report'!E32) -> 160.00005 | F34: =IF('Activity Report'!F32=0,0,'Finance Report'!F64/'Activity Report'!F32) -> 150.00006 | G34: =IF('Activity Report'!G32=0,0,'Finance Report'!G64/'Activity Report'!G32) -> 154.15106 | H34: =IF('Activity Report'!H32=0,0,'Finance Report'!H64/'Activity Report'!H32) -> 150.00009 | I34: =IF('Activity Report'!I32=0,0,'Finance Report'!I64/'Activity Report'!I32) -> 150.00011 | ... AZ34: =IF('Activity Report'!AZ32=0,0,'Finance Report'!AZ64/'Activity Report'!AZ32) -> 0
A35: Production Commissions
A36: First Thin Commission | B36: =IF('Activity Report'!B18=0,0,'Finance Report'!B66/'Activity Report'!B18) -> 0 | C36: =IF('Activity Report'!C18=0,0,'Finance Report'!C66/'Activity Report'!C18) -> 6.5623372 | D36: =IF('Activity Report'!D18=0,0,'Finance Report'!D66/'Activity Report'!D18) -> 7.5898598 | E36: =IF('Activity Report'!E18=0,0,'Finance Report'!E66/'Activity Report'!E18) -> 6.9998572 | F36: =IF('Activity Report'!F18=0,0,'Finance Report'!F66/'Activity Report'!F18) -> 6.0124564 | G36: =IF('Activity Report'!G18=0,0,'Finance Report'!G66/'Activity Report'!G18) -> 5.0987692 | H36: =IF('Activity Report'!H18=0,0,'Finance Report'!H66/'Activity Report'!H18) -> 0 | I36: =IF('Activity Report'!I18=0,0,'Finance Report'!I66/'Activity Report'!I18) -> 0 | ... AZ36: =IF('Activity Report'!AZ18=0,0,'Finance Report'!AZ66/'Activity Report'!AZ18) -> 13.122925
A37: Second Thin Commission | B37: =IF('Activity Report'!B19=0,0,'Finance Report'!B67/'Activity Report'!B19) -> 0 | C37: =IF('Activity Report'!C19=0,0,'Finance Report'!C67/'Activity Report'!C19) -> 0 | D37: =IF('Activity Report'!D19=0,0,'Finance Report'!D67/'Activity Report'!D19) -> 0 | E37: =IF('Activity Report'!E19=0,0,'Finance Report'!E67/'Activity Report'!E19) -> 11.872623 | F37: =IF('Activity Report'!F19=0,0,'Finance Report'!F67/'Activity Report'!F19) -> 16.986449 | G37: =IF('Activity Report'!G19=0,0,'Finance Report'!G67/'Activity Report'!G19) -> 20.352551 | H37: =IF('Activity Report'!H19=0,0,'Finance Report'!H67/'Activity Report'!H19) -> 13.36635 | I37: =IF('Activity Report'!I19=0,0,'Finance Report'!I67/'Activity Report'!I19) -> 14.022056 | ... AZ37: =IF('Activity Report'!AZ19=0,0,'Finance Report'!AZ67/'Activity Report'!AZ19) -> 14.22582
A38: Clearcut Commision | B38: =IF('Activity Report'!B15=0,0,'Finance Report'!B68/'Activity Report'!B15) -> 0 | C38: =IF('Activity Report'!C15=0,0,'Finance Report'!C68/'Activity Report'!C15) -> 41.800825 | D38: =IF('Activity Report'!D15=0,0,'Finance Report'!D68/'Activity Report'!D15) -> 0 | E38: =IF('Activity Report'!E15=0,0,'Finance Report'!E68/'Activity Report'!E15) -> 43.976892 | F38: =IF('Activity Report'!F15=0,0,'Finance Report'!F68/'Activity Report'!F15) -> 0 | G38: =IF('Activity Report'!G15=0,0,'Finance Report'!G68/'Activity Report'!G15) -> 36.318401 | H38: =IF('Activity Report'!H15=0,0,'Finance Report'!H68/'Activity Report'!H15) -> 0 | I38: =IF('Activity Report'!I15=0,0,'Finance Report'!I68/'Activity Report'!I15) -> 52.259845 | ... AZ38: =IF('Activity Report'!AZ15=0,0,'Finance Report'!AZ68/'Activity Report'!AZ15) -> 50.948326
A39: Hunt Lease Commission | B39: =IF('Activity Report'!B9=0,0,'Finance Report'!B70/'Activity Report'!B9) -> 0 | C39: =IF('Activity Report'!C9=0,0,'Finance Report'!C70/'Activity Report'!C9) -> 0.97470019 | D39: =IF('Activity Report'!D9=0,0,'Finance Report'!D70/'Activity Report'!D9) -> 0.97470039 | E39: =IF('Activity Report'!E9=0,0,'Finance Report'!E70/'Activity Report'!E9) -> 0.97470058 | F39: =IF('Activity Report'!F9=0,0,'Finance Report'!F70/'Activity Report'!F9) -> 0.97470078 | G39: =IF('Activity Report'!G9=0,0,'Finance Report'!G70/'Activity Report'!G9) -> 0.97470098 | H39: =IF('Activity Report'!H9=0,0,'Finance Report'!H70/'Activity Report'!H9) -> 0.97470117 | I39: =IF('Activity Report'!I9=0,0,'Finance Report'!I70/'Activity Report'!I9) -> 0.97470136 | ... AZ39: =IF('Activity Report'!AZ9=0,0,'Finance Report'!AZ70/'Activity Report'!AZ9) -> 0.97470975

Sheet Harvest Report
A1: DISCOUNTED CASH FLOW ANALYSIS
A2: Harvest Report
A3: =CONCATENATE('Model Assumptions'!B2, " - ",'Model Assumptions'!B3 ) -> IWC - Boot Hill
A4: ='Model Assumptions'!B5 -> IWC - Boothill - HSM
A6: Calendar Year >> | C6: 2026 | D6: =C6+1 -> 2027 | E6: =D6+1 -> 2028 | F6: =E6+1 -> 2029 | G6: =F6+1 -> 2030 | H6: =G6+1 -> 2031 | I6: =H6+1 -> 2032 | J6: =I6+1 -> 2033 | K6: =J6+1 -> 2034 | ... AZ6: =AY6+1 -> 2075
A7: Model Discount Period >> | B7: 0 | C7: 1 | D7: =C7+1 -> 2 | E7: =D7+1 -> 3 | F7: =E7+1 -> 4 | G7: =F7+1 -> 5 | H7: =G7+1 -> 6 | I7: =H7+1 -> 7 | J7: =I7+1 -> 8 | K7: =J7+1 -> 9 | ... AZ7: =AY7+1 -> 50
A9: Total Acres | B9: 12404.89 | C9: 12404.89 | D9: 12404.89 | E9: 12404.89 | F9: 12404.89 | G9: 12404.89 | H9: 12404.89 | I9: 12404.89 | J9: 12404.89 | K9: 12404.89 | L9: 12404.89 | M9: 12404.89 | N9: 12404.89 | O9: 12404.89 | P9: 12404.89 | Q9: 12404.89 | R9: 12404.89 | S9: 12404.89 | T9: 12404.89 | U9: 12404.89 | V9: 12404.89 | W9: 12404.89 | X9: 12404.89 | Y9: 12404.89 | Z9: 12404.89 | AA9: 12404.89 | AB9: 12404.89 | AC9: 12404.89 | AD9: 12404.89 | AE9: 12404.89 | AF9: 12404.89 | AG9: 12404.89 | AH9: 12404.89 | AI9: 12404.89 | AJ9: 12404.89 | AK9: 12404.89 | AL9: 12404.89 | AM9: 12404.89 | AN9: 12404.89 | AO9: 12404.89 | AP9: 12404.89 | AQ9: 12404.89 | AR9: 12404.89 | AS9: 12404.89 | AT9: 12404.89 | AU9: 12404.89 | AV9: 12404.89 | AW9: 12404.89 | AX9: 12404.89 | AY9: 12404.89 | AZ9: 12404.89
A10: Productive Plantation Acres | B10: 8762.98 | C10: 8762.98 | D10: 8762.98 | E10: 8762.98 | F10: 8762.98 | G10: 8762.98 | H10: 8762.98 | I10: 8762.98 | J10: 8762.98 | K10: 8762.98 | L10: 8762.98 | M10: 8762.98 | N10: 8762.98 | O10: 8762.98 | P10: 8762.98 | Q10: 8762.98 | R10: 8762.98 | S10: 8762.98 | T10: 8762.98 | U10: 8762.98 | V10: 8762.98 | W10: 8762.98 | X10: 8762.98 | Y10: 8762.98 | Z10: 8762.98 | AA10: 8762.98 | AB10: 8762.98 | AC10: 8762.98 | AD10: 8762.98 | AE10: 8762.98 | AF10: 8762.98 | AG10: 8762.98 | AH10: 8762.98 | AI10: 8762.98 | AJ10: 8762.98 | AK10: 8762.98 | AL10: 8762.98 | AM10: 8762.98 | AN10: 8762.98 | AO10: 8762.98 | AP10: 8762.98 | AQ10: 8762.98 | AR10: 8762.98 | AS10: 8762.98 | AT10: 8762.98 | AU10: 8762.98 | AV10: 8762.98 | AW10: 8762.98 | AX10: 8762.98 | AY10: 8762.98 | AZ10: 8762.98
A11: Natural Convertible Acres | B11: 611.17 | C11: 611.17 | D11: 611.17 | E11: 611.17 | F11: 611.17 | G11: 611.17 | H11: 611.17 | I11: 611.17 | J11: 611.17 | K11: 611.17 | L11: 611.17 | M11: 611.17 | N11: 611.17 | O11: 611.17 | P11: 611.17 | Q11: 611.17 | R11: 611.17 | S11: 611.17 | T11: 611.17 | U11: 611.17 | V11: 611.17 | W11: 611.17 | X11: 611.17 | Y11: 611.17 | Z11: 611.17 | AA11: 611.17 | AB11: 611.17 | AC11: 611.17 | AD11: 611.17 | AE11: 611.17 | AF11: 611.17 | AG11: 611.17 | AH11: 611.17 | AI11: 611.17 | AJ11: 611.17 | AK11: 611.17 | AL11: 611.17 | AM11: 611.17 | AN11: 611.17 | AO11: 611.17 | AP11: 611.17 | AQ11: 611.17 | AR11: 611.17 | AS11: 611.17 | AT11: 611.17 | AU11: 611.17 | AV11: 611.17 | AW11: 611.17 | AX11: 611.17 | AY11: 611.17 | AZ11: 611.17
A12: Non-Converitble Acres | B12: 3030.74 | C12: 3030.74 | D12: 3030.74 | E12: 3030.74 | F12: 3030.74 | G12: 3030.74 | H12: 3030.74 | I12: 3030.74 | J12: 3030.74 | K12: 3030.74 | L12: 3030.74 | M12: 3030.74 | N12: 3030.74 | O12: 3030.74 | P12: 3030.74 | Q12: 3030.74 | R12: 3030.74 | S12: 3030.74 | T12: 3030.74 | U12: 3030.74 | V12: 3030.74 | W12: 3030.74 | X12: 3030.74 | Y12: 3030.74 | Z12: 3030.74 | AA12: 3030.74 | AB12: 3030.74 | AC12: 3030.74 | AD12: 3030.74 | AE12: 3030.74 | AF12: 3030.74 | AG12: 3030.74 | AH12: 3030.74 | AI12: 3030.74 | AJ12: 3030.74 | AK12: 3030.74 | AL12: 3030.74 | AM12: 3030.74 | AN12: 3030.74 | AO12: 3030.74 | AP12: 3030.74 | AQ12: 3030.74 | AR12: 3030.74 | AS12: 3030.74 | AT12: 3030.74 | AU12: 3030.74 | AV12: 3030.74 | AW12: 3030.74 | AX12: 3030.74 | AY12: 3030.74 | AZ12: 3030.74
A14: Harvest Acres | B14: 0 | C14: 919.96 | D14: 193.34 | E14: 699.1804 | F14: 576.8 | G14: 421.71 | H14: 119.68 | I14: 645.2214 | J14: 1479.316 | K14: 817.0594 | L14: 703.2174 | M14: 459.6524 | N14: 1242.6004 | O14: 662.5206 | P14: 1338.2898 | Q14: 929.28 | R14: 809.49 | S14: 453.22 | T14: 213.74 | U14: 981.9564 | V14: 273.6928 | W14: 365.9684 | X14: 254.00407 | Y14: 1626.1983 | Z14: 2098.8264 | AA14: 251.34 | AB14: 664.15 | AC14: 345.62 | AD14: 1058.01 | AE14: 251.9736 | AF14: 1081.33 | AG14: 1402.99 | AH14: 347.19 | AI14: 215.14 | AJ14: 984.0868 | AK14: 858.55 | AL14: 412.0532 | AM14: 337.29 | AN14: 1312.085 | AO14: 1667.4954 | AP14: 1326.6564 | AQ14: 681.69 | AR14: 558.9724 | AS14: 1125.025 | AT14: 207.81 | AU14: 1193.5536 | AV14: 577.3024 | AW14: 186.6002 | AX14: 330.6838 | AY14: 1501.39 | AZ14: 2222.5636
A15: Total Harvest Volume (tons) | B15: 0 | C15: 47414.973 | D15: 4751.7809 | E15: 61308.341 | F15: 19745.034 | G15: 23397.271 | H15: 2857.348 | I15: 66441.282 | J15: 89801.794 | K15: 56532.3 | L15: 57588.441 | M15: 45747.972 | N15: 132949.63 | O15: 26330.913 | P15: 96057.543 | Q15: 81707.906 | R15: 45318.094 | S15: 16359.018 | T15: 17890.641 | U15: 53193.448 | V15: 23838.226 | W15: 13810.017 | X15: 38950.185 | Y15: 133120.2 | Z15: 238627.42 | AA15: 14458.257 | AB15: 21431.415 | AC15: 13415.615 | AD15: 42202.378 | AE15: 26087.256 | AF15: 40687.067 | AG15: 79747.543 | AH15: 27593.294 | AI15: 12223.322 | AJ15: 74817.252 | AK15: 32247.983 | AL15: 21118.63 | AM15: 9643.3586 | AN15: 102286.55 | AO15: 106829.67 | AP15: 44890.272 | AQ15: 45470.353 | AR15: 46208.697 | AS15: 111441.86 | AT15: 9743.998 | AU15: 81938.098 | AV15: 69260.061 | AW15: 5312.4927 | AX15: 7471.1763 | AY15: 133175 | AZ15: 166268.65
A16: Pine Large Saw Timber | B16: 0 | C16: 1498.1175 | D16: 0 | E16: 2964.9441 | F16: 162.81051 | G16: 332.31952 | H16: 0 | I16: 2170.11 | J16: 391.68203 | K16: 0 | L16: 0 | M16: 176.91779 | N16: 8943.018 | O16: 17.180887 | P16: 273.91626 | Q16: 214.47303 | R16: 692.74119 | S16: 264.97248 | T16: 40.363068 | U16: 2820.199 | V16: 625.60038 | W16: 14.94796 | X16: 0 | Y16: 23.949768 | Z16: 33442.975 | AA16: 100.29704 | AB16: 28.597095 | AC16: 0 | AD16: 1740.3532 | AE16: 5046.9542 | AF16: 85.851185 | AG16: 1304.0859 | AH16: 2402.3533 | AI16: 0 | AJ16: 16547.826 | AK16: 77.506328 | AL16: 961.25851 | AM16: 6.169023 | AN16: 12587.13 | AO16: 6100.3956 | AP16: 0 | AQ16: 3.992679 | AR16: 16.884585 | AS16: 9459.3367 | AT16: 0 | AU16: 1164.05 | AV16: 139.81642 | AW16: 10.319764 | AX16: 4.1222422 | AY16: 4668.9147 | AZ16: 4320.0348
A17: Tons/Acre | B17: =IF(B16=0,0,B16/B$14) -> 0 | C17: =IF(C16=0,0,C16/C$14) -> 1.6284594 | D17: =IF(D16=0,0,D16/D$14) -> 0 | E17: =IF(E16=0,0,E16/E$14) -> 4.2405996 | F17: =IF(F16=0,0,F16/F$14) -> 0.28226509 | G17: =IF(G16=0,0,G16/G$14) -> 0.78802855 | H17: =IF(H16=0,0,H16/H$14) -> 0 | I17: =IF(I16=0,0,I16/I$14) -> 3.3633571 | ... AZ17: =IF(AZ16=0,0,AZ16/AZ$14) -> 1.9437171
A18: Pine Sawtimber | B18: 0 | C18: 678.1187 | D18: 22.062283 | E18: 1187.6678 | F18: 0 | G18: 200.59973 | H18: 11.273856 | I18: 2096.4404 | J18: 1807.5501 | K18: 127.93901 | L18: 2176.8839 | M18: 6408.5779 | N18: 8890.6326 | O18: 426.09889 | P18: 7595.1671 | Q18: 18812.231 | R18: 1262.7054 | S18: 126.48941 | T18: 1919.8263 | U18: 1293.6365 | V18: 1766.8829 | W18: 2566.9074 | X18: 17001.716 | Y18: 17988.442 | Z18: 29972.563 | AA18: 0 | AB18: 0 | AC18: 0 | AD18: 0.544752 | AE18: 3168.2347 | AF18: 0 | AG18: 608.26832 | AH18: 1642.4434 | AI18: 125.28598 | AJ18: 450.63396 | AK18: 0.614592 | AL18: 31.152279 | AM18: 0 | AN18: 8787.1829 | AO18: 30561.883 | AP18: 25.055394 | AQ18: 13771.544 | AR18: 12713.628 | AS18: 12149.188 | AT18: 1263.041 | AU18: 5440.4405 | AV18: 33216.445 | AW18: 64.43744 | AX18: 104.99762 | AY18: 10153.318 | AZ18: 6077.301
A19: Tons/Acre | B19: =IF(B18=0,0,B18/B$14) -> 0 | C19: =IF(C18=0,0,C18/C$14) -> 0.73711759 | D19: =IF(D18=0,0,D18/D$14) -> 0.11411132 | E19: =IF(E18=0,0,E18/E$14) -> 1.6986571 | F19: =IF(F18=0,0,F18/F$14) -> 0 | G19: =IF(G18=0,0,G18/G$14) -> 0.47568171 | H19: =IF(H18=0,0,H18/H$14) -> 0.0942 | I19: =IF(I18=0,0,I18/I$14) -> 3.2491799 | ... AZ19: =IF(AZ18=0,0,AZ18/AZ$14) -> 2.7343654
A20: Pine Chip-n-Saw | B20: 0 | C20: 28179.922 | D20: 1552.6814 | E20: 33160.264 | F20: 7214.5042 | G20: 10315.016 | H20: 2250.1516 | I20: 45763.124 | J20: 52466.978 | K20: 19787.546 | L20: 34757.179 | M20: 28817.147 | N20: 72258.897 | O20: 4788.327 | P20: 54895.259 | Q20: 44670.597 | R20: 26582.179 | S20: 7990.6019 | T20: 11753.985 | U20: 31419.996 | V20: 15460.601 | W20: 6796.8094 | X20: 14744.306 | Y20: 77027.982 | Z20: 101794.33 | AA20: 11505.422 | AB20: 13545.431 | AC20: 5644.838 | AD20: 14807.857 | AE20: 9337.3698 | AF20: 22955.03 | AG20: 55968.524 | AH20: 14674.815 | AI20: 9906.9573 | AJ20: 30626.518 | AK20: 21967.85 | AL20: 11587.81 | AM20: 6426.1655 | AN20: 50880.775 | AO20: 31121.891 | AP20: 16409.415 | AQ20: 22461.497 | AR20: 26565.597 | AS20: 66029.675 | AT20: 5644.692 | AU20: 58413.742 | AV20: 25631.27 | AW20: 1923.8276 | AX20: 2434.8363 | AY20: 89222.802 | AZ20: 117477.55
A21: Tons/Acre | B21: =IF(B20=0,0,B20/B$14) -> 0 | C21: =IF(C20=0,0,C20/C$14) -> 30.631682 | D21: =IF(D20=0,0,D20/D$14) -> 8.030834 | E21: =IF(E20=0,0,E20/E$14) -> 47.427336 | F21: =IF(F20=0,0,F20/F$14) -> 12.507809 | G21: =IF(G20=0,0,G20/G$14) -> 24.459975 | H21: =IF(H20=0,0,H20/H$14) -> 18.8014 | I21: =IF(I20=0,0,I20/I$14) -> 70.926234 | ... AZ21: =IF(AZ20=0,0,AZ20/AZ$14) -> 52.856776
A22: Pine Pulpwood | B22: 0 | C22: 14847.122 | D22: 3177.0371 | E22: 19263.949 | F22: 12367.719 | G22: 11948.107 | H22: 595.92262 | I22: 14212.172 | J22: 34420.76 | K22: 36486.91 | L22: 20373.646 | M22: 9667.9841 | N22: 38740.781 | O22: 21050.563 | P22: 32469.605 | Q22: 17877.15 | R22: 16734.502 | S22: 7976.9542 | T22: 4004.2446 | U22: 17659.617 | V22: 5338.9829 | W22: 4417.8094 | X22: 7128.2433 | Y22: 37967.456 | Z22: 73417.55 | AA22: 2852.5374 | AB22: 7857.3871 | AC22: 7770.7774 | AD22: 25653.623 | AE22: 8534.6978 | AF22: 17646.186 | AG22: 21866.665 | AH22: 8873.6815 | AI22: 2191.0787 | AJ22: 27186.947 | AK22: 10202.012 | AL22: 8518.9879 | AM22: 3211.0241 | AN22: 29752.491 | AO22: 38955.96 | AP22: 28455.802 | AQ22: 9233.3191 | AR22: 6715.6351 | AS22: 23396.989 | AT22: 2836.265 | AU22: 16919.865 | AV22: 9831.6612 | AW22: 3281.3676 | AX22: 4914.2218 | AY22: 27437.949 | AZ22: 38393.768
A23: Tons/Acre | B23: =IF(B22=0,0,B22/B$14) -> 0 | C23: =IF(C22=0,0,C22/C$14) -> 16.138878 | D23: =IF(D22=0,0,D22/D$14) -> 16.432384 | E23: =IF(E22=0,0,E22/E$14) -> 27.552186 | F23: =IF(F22=0,0,F22/F$14) -> 21.441954 | G23: =IF(G22=0,0,G22/G$14) -> 28.332519 | H23: =IF(H22=0,0,H22/H$14) -> 4.9793 | I23: =IF(I22=0,0,I22/I$14) -> 22.026814 | ... AZ23: =IF(AZ22=0,0,AZ22/AZ$14) -> 17.274542
A24: Hardwood Sawtimber | B24: 0 | C24: 335.78893 | D24: 0 | E24: 569.44043 | F24: 0 | G24: 72.061585 | H24: 0 | I24: 252.34545 | J24: 52.68087 | K24: 9.5890075 | L24: 21.766297 | M24: 203.87142 | N24: 538.59126 | O24: 20.243075 | P24: 335.95217 | Q24: 32.964104 | R24: 2.480963 | S24: 0 | T24: 58.357762 | U24: 0 | V24: 47.936062 | W24: 0.57452828 | X24: 3.2208712 | Y24: 4.7674258 | Z24: 0 | AA24: 0 | AB24: 0 | AC24: 0 | AD24: 0 | AE24: 0 | AF24: 0 | AG24: 0 | AH24: 0 | AI24: 0 | AJ24: 0.9684287 | AK24: 0 | AL24: 3.5958789 | AM24: 0 | AN24: 19.058427 | AO24: 0 | AP24: 0 | AQ24: 0 | AR24: 14.801522 | AS24: 26.536905 | AT24: 0 | AU24: 0 | AV24: 163.21766 | AW24: 12.046995 | AX24: 4.8121867 | AY24: 646.75535 | AZ24: 0
A25: Tons/Acre | B25: =IF(B24=0,0,B24/B$14) -> 0 | C25: =IF(C24=0,0,C24/C$14) -> 0.36500383 | D25: =IF(D24=0,0,D24/D$14) -> 0 | E25: =IF(E24=0,0,E24/E$14) -> 0.81443993 | F25: =IF(F24=0,0,F24/F$14) -> 0 | G25: =IF(G24=0,0,G24/G$14) -> 0.17087948 | H25: =IF(H24=0,0,H24/H$14) -> 0 | I25: =IF(I24=0,0,I24/I$14) -> 0.39109902 | ... AZ25: =IF(AZ24=0,0,AZ24/AZ$14) -> 0
